2025-10-19 20:35:45,277 [WARNING] userdata/uinfo.json not found, creating new file...
2025-10-19 20:35:45,277 [ERROR] Failed to write to userdata/uinfo.json: [Errno 2] No such file or directory: 'userdata/uinfo.json'
2025-10-19 20:35:57,539 [INFO] logging in using static token
2025-10-19 20:35:59,048 [INFO] Shard ID None has connected to Gateway (Session ID: a3e6b1e344795b1815ae4bdf74d5c765).
2025-10-19 20:36:01,054 [INFO] Logged in as BestBotEver!!!#9403 (ID: 1386280922218893465)
2025-10-19 20:36:01,396 [INFO] BestBotEver!!!#9403 (1386280922218893465) in #üí¨-chat-‚úâÔ∏è (1371357608904228924): Bot 1.8.0
2025-10-19 20:36:01,447 [INFO] Sent startup message to channel ID: 1371357608904228924
2025-10-19 20:36:02,011 [ERROR] Failed to write to userdata/uinfo.json: [Errno 2] No such file or directory: 'userdata/uinfo.json'
2025-10-19 20:36:02,012 [INFO] Auto-saved 34 users at 2025-10-19 20:36:01
2025-10-19 20:36:02,417 [ERROR] Failed to write to userdata/uinfo.json: [Errno 2] No such file or directory: 'userdata/uinfo.json'
2025-10-19 20:36:02,417 [INFO] Auto-saved 34 users at 2025-10-19 20:36:01
2025-10-19 20:36:02,477 [INFO] p.pumpum (1260198579067420722) in #üéÆ-gaming-üïπÔ∏è (1395783584253739141): ‡πÄ‡∏•‡πà‡∏ô
2025-10-19 20:36:18,701 [INFO] tatthep0270 (1340262742782771323) in #üéÆ-gaming-üïπÔ∏è (1395783584253739141): ‡πÄ‡∏Ç‡πâ‡∏≤‡∏°‡∏≤
2025-10-19 20:36:50,118 [WARNING] Shard ID None heartbeat blocked for more than 10 seconds.
Loop thread traceback (most recent call last):
  File "C:\Users\jimnd\AppData\Local\Programs\Python\Python313\Lib\threading.py", line 1014, in _bootstrap
    self._bootstrap_inner()
  File "C:\Users\jimnd\AppData\Local\Programs\Python\Python313\Lib\threading.py", line 1043, in _bootstrap_inner
    self.run()
  File "C:\Users\jimnd\AppData\Local\Programs\Python\Python313\Lib\threading.py", line 994, in run
    self._target(*self._args, **self._kwargs)
  File "C:\Users\jimnd\Desktop\BestDiscordBotEver\main.py", line 931, in run_bot
    bot_loop.run_until_complete(bot.start(token))
  File "C:\Users\jimnd\AppData\Local\Programs\Python\Python313\Lib\asyncio\base_events.py", line 712, in run_until_complete
    self.run_forever()
  File "C:\Users\jimnd\AppData\Local\Programs\Python\Python313\Lib\asyncio\base_events.py", line 683, in run_forever
    self._run_once()
  File "C:\Users\jimnd\AppData\Local\Programs\Python\Python313\Lib\asyncio\base_events.py", line 2042, in _run_once
    handle._run()
  File "C:\Users\jimnd\AppData\Local\Programs\Python\Python313\Lib\asyncio\events.py", line 89, in _run
    self._context.run(self._callback, *self._args)
  File "C:\Users\jimnd\AppData\Local\Programs\Python\Python313\Lib\site-packages\discord\client.py", line 481, in _run_event
    await coro(*args, **kwargs)
  File "C:\Users\jimnd\Desktop\BestDiscordBotEver\main.py", line 452, in on_message
    logging.info(
  File "C:\Users\jimnd\AppData\Local\Programs\Python\Python313\Lib\logging\__init__.py", line 2208, in info
    root.info(msg, *args, **kwargs)
  File "C:\Users\jimnd\AppData\Local\Programs\Python\Python313\Lib\logging\__init__.py", line 1522, in info
    self._log(INFO, msg, args, **kwargs)
  File "C:\Users\jimnd\AppData\Local\Programs\Python\Python313\Lib\logging\__init__.py", line 1667, in _log
    self.handle(record)
  File "C:\Users\jimnd\AppData\Local\Programs\Python\Python313\Lib\logging\__init__.py", line 1686, in handle
    self.callHandlers(record)
  File "C:\Users\jimnd\AppData\Local\Programs\Python\Python313\Lib\logging\__init__.py", line 1744, in callHandlers
    hdlr.handle(record)
  File "C:\Users\jimnd\AppData\Local\Programs\Python\Python313\Lib\logging\__init__.py", line 1027, in handle
    self.emit(record)
  File "C:\Users\jimnd\AppData\Local\Programs\Python\Python313\Lib\logging\__init__.py", line 1155, in emit
    self.flush()
  File "C:\Users\jimnd\AppData\Local\Programs\Python\Python313\Lib\logging\__init__.py", line 1137, in flush
    self.stream.flush()

2025-10-19 20:38:14,693 [INFO] Shard ID None session has been invalidated.
2025-10-19 20:38:20,946 [INFO] Shard ID None has connected to Gateway (Session ID: c8afced1eecfbbbb4cf02a74c4dd90a8).
2025-10-19 20:38:22,952 [INFO] Logged in as BestBotEver!!!#9403 (ID: 1386280922218893465)
2025-10-19 20:38:23,309 [INFO] BestBotEver!!!#9403 (1386280922218893465) in #üí¨-chat-‚úâÔ∏è (1371357608904228924): Bot 1.8.0
2025-10-19 20:38:23,335 [INFO] Sent startup message to channel ID: 1371357608904228924
2025-10-19 20:38:23,335 [ERROR] Ignoring exception in on_ready
Traceback (most recent call last):
  File "C:\Users\jimnd\AppData\Local\Programs\Python\Python313\Lib\site-packages\discord\client.py", line 481, in _run_event
    await coro(*args, **kwargs)
  File "C:\Users\jimnd\Desktop\BestDiscordBotEver\main.py", line 447, in on_ready
    auto_save_users.start()
    ~~~~~~~~~~~~~~~~~~~~~^^
  File "C:\Users\jimnd\AppData\Local\Programs\Python\Python313\Lib\site-packages\discord\ext\tasks\__init__.py", line 400, in start
    raise RuntimeError('Task is already launched and is not completed.')
RuntimeError: Task is already launched and is not completed.
